[2023-05-04T14:42:27.799-0300] {taskinstance.py:1090} INFO - Dependencies all met for dep_context=non-requeueable deps ti=<TaskInstance: NorthwindELT.export_final_output manual__2023-05-04T17:40:30.018510+00:00 [queued]>
[2023-05-04T14:42:27.811-0300] {taskinstance.py:1090} INFO - Dependencies all met for dep_context=requeueable deps ti=<TaskInstance: NorthwindELT.export_final_output manual__2023-05-04T17:40:30.018510+00:00 [queued]>
[2023-05-04T14:42:27.812-0300] {taskinstance.py:1288} INFO - 
--------------------------------------------------------------------------------
[2023-05-04T14:42:27.813-0300] {taskinstance.py:1289} INFO - Starting attempt 2 of 3
[2023-05-04T14:42:27.814-0300] {taskinstance.py:1290} INFO - 
--------------------------------------------------------------------------------
[2023-05-04T14:42:27.841-0300] {taskinstance.py:1309} INFO - Executing <Task(PythonOperator): export_final_output> on 2023-05-04 17:40:30.018510+00:00
[2023-05-04T14:42:27.845-0300] {standard_task_runner.py:55} INFO - Started process 10494 to run task
[2023-05-04T14:42:27.851-0300] {standard_task_runner.py:82} INFO - Running: ['airflow', 'tasks', 'run', 'NorthwindELT', 'export_final_output', 'manual__2023-05-04T17:40:30.018510+00:00', '--job-id', '23', '--raw', '--subdir', 'DAGS_FOLDER/etl_northwind.py', '--cfg-path', '/tmp/tmpxdkiomct']
[2023-05-04T14:42:27.853-0300] {standard_task_runner.py:83} INFO - Job 23: Subtask export_final_output
[2023-05-04T14:42:27.932-0300] {task_command.py:389} INFO - Running <TaskInstance: NorthwindELT.export_final_output manual__2023-05-04T17:40:30.018510+00:00 [running]> on host DESKTOP-28FM47R.
[2023-05-04T14:42:28.002-0300] {taskinstance.py:1516} INFO - Exporting the following env vars:
AIRFLOW_CTX_DAG_EMAIL=airflow@example.com
AIRFLOW_CTX_DAG_OWNER=airflow
AIRFLOW_CTX_DAG_ID=NorthwindELT
AIRFLOW_CTX_TASK_ID=export_final_output
AIRFLOW_CTX_EXECUTION_DATE=2023-05-04T17:40:30.018510+00:00
AIRFLOW_CTX_TRY_NUMBER=2
AIRFLOW_CTX_DAG_RUN_ID=manual__2023-05-04T17:40:30.018510+00:00
[2023-05-04T14:42:28.004-0300] {taskinstance.py:1776} ERROR - Task failed with exception
Traceback (most recent call last):
  File "/home/lcscarv/projetos/indicium/desafio_5/.venv/lib/python3.8/site-packages/airflow/operators/python.py", line 175, in execute
    return_value = self.execute_callable()
  File "/home/lcscarv/projetos/indicium/desafio_5/.venv/lib/python3.8/site-packages/airflow/operators/python.py", line 192, in execute_callable
    return self.python_callable(*self.op_args, **self.op_kwargs)
  File "/home/lcscarv/projetos/indicium/desafio_5/airflow_data/dags/etl_northwind.py", line 52, in export_final_answer
    with open('airflow_data/data/count.txt') as f:
FileNotFoundError: [Errno 2] No such file or directory: 'airflow_data/data/count.txt'
[2023-05-04T14:42:28.010-0300] {taskinstance.py:1327} INFO - Marking task as UP_FOR_RETRY. dag_id=NorthwindELT, task_id=export_final_output, execution_date=20230504T174030, start_date=20230504T174227, end_date=20230504T174228
[2023-05-04T14:42:28.033-0300] {logging_mixin.py:137} WARNING - /home/lcscarv/projetos/indicium/desafio_5/.venv/lib/python3.8/site-packages/airflow/utils/email.py:152 RemovedInAirflow3Warning: Fetching SMTP credentials from configuration variables will be deprecated in a future release. Please set credentials using a connection instead.
[2023-05-04T14:42:28.033-0300] {configuration.py:664} WARNING - section/key [smtp/smtp_user] not found in config
[2023-05-04T14:42:28.033-0300] {email.py:268} INFO - Email alerting: attempt 1
[2023-05-04T14:42:28.038-0300] {configuration.py:664} WARNING - section/key [smtp/smtp_user] not found in config
[2023-05-04T14:42:28.039-0300] {email.py:268} INFO - Email alerting: attempt 1
[2023-05-04T14:42:28.039-0300] {taskinstance.py:1839} ERROR - Failed to send email to: ['airflow@example.com']
Traceback (most recent call last):
  File "/home/lcscarv/projetos/indicium/desafio_5/.venv/lib/python3.8/site-packages/airflow/models/taskinstance.py", line 1383, in _run_raw_task
    self._execute_task_with_callbacks(context, test_mode)
  File "/home/lcscarv/projetos/indicium/desafio_5/.venv/lib/python3.8/site-packages/airflow/models/taskinstance.py", line 1529, in _execute_task_with_callbacks
    result = self._execute_task(context, task_orig)
  File "/home/lcscarv/projetos/indicium/desafio_5/.venv/lib/python3.8/site-packages/airflow/models/taskinstance.py", line 1589, in _execute_task
    result = execute_callable(context=context)
  File "/home/lcscarv/projetos/indicium/desafio_5/.venv/lib/python3.8/site-packages/airflow/operators/python.py", line 175, in execute
    return_value = self.execute_callable()
  File "/home/lcscarv/projetos/indicium/desafio_5/.venv/lib/python3.8/site-packages/airflow/operators/python.py", line 192, in execute_callable
    return self.python_callable(*self.op_args, **self.op_kwargs)
  File "/home/lcscarv/projetos/indicium/desafio_5/airflow_data/dags/etl_northwind.py", line 52, in export_final_answer
    with open('airflow_data/data/count.txt') as f:
FileNotFoundError: [Errno 2] No such file or directory: 'airflow_data/data/count.txt'

During handling of the above exception, another exception occurred:

Traceback (most recent call last):
  File "/home/lcscarv/projetos/indicium/desafio_5/.venv/lib/python3.8/site-packages/airflow/models/taskinstance.py", line 2239, in email_alert
    send_email(task.email, subject, html_content)
  File "/home/lcscarv/projetos/indicium/desafio_5/.venv/lib/python3.8/site-packages/airflow/utils/email.py", line 78, in send_email
    return backend(
  File "/home/lcscarv/projetos/indicium/desafio_5/.venv/lib/python3.8/site-packages/airflow/utils/email.py", line 152, in send_email_smtp
    send_mime_email(e_from=mail_from, e_to=recipients, mime_msg=msg, conn_id=conn_id, dryrun=dryrun)
  File "/home/lcscarv/projetos/indicium/desafio_5/.venv/lib/python3.8/site-packages/airflow/utils/email.py", line 270, in send_mime_email
    smtp_conn = _get_smtp_connection(smtp_host, smtp_port, smtp_timeout, smtp_ssl)
  File "/home/lcscarv/projetos/indicium/desafio_5/.venv/lib/python3.8/site-packages/airflow/utils/email.py", line 317, in _get_smtp_connection
    else smtplib.SMTP(host=host, port=port, timeout=timeout)
  File "/usr/lib/python3.8/smtplib.py", line 255, in __init__
    (code, msg) = self.connect(host, port)
  File "/usr/lib/python3.8/smtplib.py", line 339, in connect
    self.sock = self._get_socket(host, port, self.timeout)
  File "/usr/lib/python3.8/smtplib.py", line 310, in _get_socket
    return socket.create_connection((host, port), timeout,
  File "/usr/lib/python3.8/socket.py", line 808, in create_connection
    raise err
  File "/usr/lib/python3.8/socket.py", line 796, in create_connection
    sock.connect(sa)
ConnectionRefusedError: [Errno 111] Connection refused

During handling of the above exception, another exception occurred:

Traceback (most recent call last):
  File "/home/lcscarv/projetos/indicium/desafio_5/.venv/lib/python3.8/site-packages/airflow/models/taskinstance.py", line 1837, in handle_failure
    self.email_alert(error, task)
  File "/home/lcscarv/projetos/indicium/desafio_5/.venv/lib/python3.8/site-packages/airflow/models/taskinstance.py", line 2241, in email_alert
    send_email(task.email, subject, html_content_err)
  File "/home/lcscarv/projetos/indicium/desafio_5/.venv/lib/python3.8/site-packages/airflow/utils/email.py", line 78, in send_email
    return backend(
  File "/home/lcscarv/projetos/indicium/desafio_5/.venv/lib/python3.8/site-packages/airflow/utils/email.py", line 152, in send_email_smtp
    send_mime_email(e_from=mail_from, e_to=recipients, mime_msg=msg, conn_id=conn_id, dryrun=dryrun)
  File "/home/lcscarv/projetos/indicium/desafio_5/.venv/lib/python3.8/site-packages/airflow/utils/email.py", line 270, in send_mime_email
    smtp_conn = _get_smtp_connection(smtp_host, smtp_port, smtp_timeout, smtp_ssl)
  File "/home/lcscarv/projetos/indicium/desafio_5/.venv/lib/python3.8/site-packages/airflow/utils/email.py", line 317, in _get_smtp_connection
    else smtplib.SMTP(host=host, port=port, timeout=timeout)
  File "/usr/lib/python3.8/smtplib.py", line 255, in __init__
    (code, msg) = self.connect(host, port)
  File "/usr/lib/python3.8/smtplib.py", line 339, in connect
    self.sock = self._get_socket(host, port, self.timeout)
  File "/usr/lib/python3.8/smtplib.py", line 310, in _get_socket
    return socket.create_connection((host, port), timeout,
  File "/usr/lib/python3.8/socket.py", line 808, in create_connection
    raise err
  File "/usr/lib/python3.8/socket.py", line 796, in create_connection
    sock.connect(sa)
ConnectionRefusedError: [Errno 111] Connection refused
[2023-05-04T14:42:28.057-0300] {standard_task_runner.py:100} ERROR - Failed to execute job 23 for task export_final_output ([Errno 2] No such file or directory: 'airflow_data/data/count.txt'; 10494)
[2023-05-04T14:42:28.066-0300] {local_task_job.py:212} INFO - Task exited with return code 1
[2023-05-04T14:42:28.078-0300] {taskinstance.py:2596} INFO - 0 downstream tasks scheduled from follow-on schedule check
