[2023-05-03T14:02:01.669-0300] {taskinstance.py:1090} INFO - Dependencies all met for dep_context=non-requeueable deps ti=<TaskInstance: NorthwindELT.northwind_extract_ord_det manual__2023-05-03T16:49:10.333098+00:00 [queued]>
[2023-05-03T14:02:01.683-0300] {taskinstance.py:1090} INFO - Dependencies all met for dep_context=requeueable deps ti=<TaskInstance: NorthwindELT.northwind_extract_ord_det manual__2023-05-03T16:49:10.333098+00:00 [queued]>
[2023-05-03T14:02:01.683-0300] {taskinstance.py:1288} INFO - 
--------------------------------------------------------------------------------
[2023-05-03T14:02:01.683-0300] {taskinstance.py:1289} INFO - Starting attempt 4 of 5
[2023-05-03T14:02:01.684-0300] {taskinstance.py:1290} INFO - 
--------------------------------------------------------------------------------
[2023-05-03T14:02:01.710-0300] {taskinstance.py:1309} INFO - Executing <Task(PythonOperator): northwind_extract_ord_det> on 2023-05-03 16:49:10.333098+00:00
[2023-05-03T14:02:01.715-0300] {standard_task_runner.py:55} INFO - Started process 30241 to run task
[2023-05-03T14:02:01.720-0300] {standard_task_runner.py:82} INFO - Running: ['airflow', 'tasks', 'run', 'NorthwindELT', 'northwind_extract_ord_det', 'manual__2023-05-03T16:49:10.333098+00:00', '--job-id', '20', '--raw', '--subdir', 'DAGS_FOLDER/etl_northwind.py', '--cfg-path', '/tmp/tmpplseut6o']
[2023-05-03T14:02:01.722-0300] {standard_task_runner.py:83} INFO - Job 20: Subtask northwind_extract_ord_det
[2023-05-03T14:02:01.801-0300] {task_command.py:389} INFO - Running <TaskInstance: NorthwindELT.northwind_extract_ord_det manual__2023-05-03T16:49:10.333098+00:00 [running]> on host DESKTOP-28FM47R.
[2023-05-03T14:02:01.871-0300] {taskinstance.py:1516} INFO - Exporting the following env vars:
AIRFLOW_CTX_DAG_EMAIL=airflow@example.com
AIRFLOW_CTX_DAG_OWNER=airflow
AIRFLOW_CTX_DAG_ID=NorthwindELT
AIRFLOW_CTX_TASK_ID=northwind_extract_ord_det
AIRFLOW_CTX_EXECUTION_DATE=2023-05-03T16:49:10.333098+00:00
AIRFLOW_CTX_TRY_NUMBER=4
AIRFLOW_CTX_DAG_RUN_ID=manual__2023-05-03T16:49:10.333098+00:00
[2023-05-03T14:02:02.615-0300] {taskinstance.py:1776} ERROR - Task failed with exception
Traceback (most recent call last):
  File "/home/lcscarv/projetos/indicium/desafio_5/.venv/lib/python3.8/site-packages/airflow/operators/python.py", line 175, in execute
    return_value = self.execute_callable()
  File "/home/lcscarv/projetos/indicium/desafio_5/.venv/lib/python3.8/site-packages/airflow/operators/python.py", line 192, in execute_callable
    return self.python_callable(*self.op_args, **self.op_kwargs)
  File "/home/lcscarv/projetos/indicium/desafio_5/airflow_data/dags/etl_northwind.py", line 32, in bd_connect_dag_2
    orders_info = pd.merge(order_df,order_detail_df,left_on='Id', right_on='OrderId', how='inner')
  File "/home/lcscarv/projetos/indicium/desafio_5/.venv/lib/python3.8/site-packages/pandas/core/reshape/merge.py", line 144, in merge
    op = _MergeOperation(
  File "/home/lcscarv/projetos/indicium/desafio_5/.venv/lib/python3.8/site-packages/pandas/core/reshape/merge.py", line 737, in __init__
    self._maybe_coerce_merge_keys()
  File "/home/lcscarv/projetos/indicium/desafio_5/.venv/lib/python3.8/site-packages/pandas/core/reshape/merge.py", line 1389, in _maybe_coerce_merge_keys
    raise ValueError(msg)
ValueError: You are trying to merge on object and int64 columns. If you wish to proceed you should use pd.concat
[2023-05-03T14:02:02.627-0300] {taskinstance.py:1327} INFO - Marking task as UP_FOR_RETRY. dag_id=NorthwindELT, task_id=northwind_extract_ord_det, execution_date=20230503T164910, start_date=20230503T170201, end_date=20230503T170202
[2023-05-03T14:02:02.649-0300] {logging_mixin.py:137} WARNING - /home/lcscarv/projetos/indicium/desafio_5/.venv/lib/python3.8/site-packages/airflow/utils/email.py:152 RemovedInAirflow3Warning: Fetching SMTP credentials from configuration variables will be deprecated in a future release. Please set credentials using a connection instead.
[2023-05-03T14:02:02.649-0300] {configuration.py:664} WARNING - section/key [smtp/smtp_user] not found in config
[2023-05-03T14:02:02.650-0300] {email.py:268} INFO - Email alerting: attempt 1
[2023-05-03T14:02:02.656-0300] {configuration.py:664} WARNING - section/key [smtp/smtp_user] not found in config
[2023-05-03T14:02:02.656-0300] {email.py:268} INFO - Email alerting: attempt 1
[2023-05-03T14:02:02.657-0300] {taskinstance.py:1839} ERROR - Failed to send email to: ['airflow@example.com']
Traceback (most recent call last):
  File "/home/lcscarv/projetos/indicium/desafio_5/.venv/lib/python3.8/site-packages/airflow/models/taskinstance.py", line 1383, in _run_raw_task
    self._execute_task_with_callbacks(context, test_mode)
  File "/home/lcscarv/projetos/indicium/desafio_5/.venv/lib/python3.8/site-packages/airflow/models/taskinstance.py", line 1529, in _execute_task_with_callbacks
    result = self._execute_task(context, task_orig)
  File "/home/lcscarv/projetos/indicium/desafio_5/.venv/lib/python3.8/site-packages/airflow/models/taskinstance.py", line 1589, in _execute_task
    result = execute_callable(context=context)
  File "/home/lcscarv/projetos/indicium/desafio_5/.venv/lib/python3.8/site-packages/airflow/operators/python.py", line 175, in execute
    return_value = self.execute_callable()
  File "/home/lcscarv/projetos/indicium/desafio_5/.venv/lib/python3.8/site-packages/airflow/operators/python.py", line 192, in execute_callable
    return self.python_callable(*self.op_args, **self.op_kwargs)
  File "/home/lcscarv/projetos/indicium/desafio_5/airflow_data/dags/etl_northwind.py", line 32, in bd_connect_dag_2
    orders_info = pd.merge(order_df,order_detail_df,left_on='Id', right_on='OrderId', how='inner')
  File "/home/lcscarv/projetos/indicium/desafio_5/.venv/lib/python3.8/site-packages/pandas/core/reshape/merge.py", line 144, in merge
    op = _MergeOperation(
  File "/home/lcscarv/projetos/indicium/desafio_5/.venv/lib/python3.8/site-packages/pandas/core/reshape/merge.py", line 737, in __init__
    self._maybe_coerce_merge_keys()
  File "/home/lcscarv/projetos/indicium/desafio_5/.venv/lib/python3.8/site-packages/pandas/core/reshape/merge.py", line 1389, in _maybe_coerce_merge_keys
    raise ValueError(msg)
ValueError: You are trying to merge on object and int64 columns. If you wish to proceed you should use pd.concat

During handling of the above exception, another exception occurred:

Traceback (most recent call last):
  File "/home/lcscarv/projetos/indicium/desafio_5/.venv/lib/python3.8/site-packages/airflow/models/taskinstance.py", line 2239, in email_alert
    send_email(task.email, subject, html_content)
  File "/home/lcscarv/projetos/indicium/desafio_5/.venv/lib/python3.8/site-packages/airflow/utils/email.py", line 78, in send_email
    return backend(
  File "/home/lcscarv/projetos/indicium/desafio_5/.venv/lib/python3.8/site-packages/airflow/utils/email.py", line 152, in send_email_smtp
    send_mime_email(e_from=mail_from, e_to=recipients, mime_msg=msg, conn_id=conn_id, dryrun=dryrun)
  File "/home/lcscarv/projetos/indicium/desafio_5/.venv/lib/python3.8/site-packages/airflow/utils/email.py", line 270, in send_mime_email
    smtp_conn = _get_smtp_connection(smtp_host, smtp_port, smtp_timeout, smtp_ssl)
  File "/home/lcscarv/projetos/indicium/desafio_5/.venv/lib/python3.8/site-packages/airflow/utils/email.py", line 317, in _get_smtp_connection
    else smtplib.SMTP(host=host, port=port, timeout=timeout)
  File "/usr/lib/python3.8/smtplib.py", line 255, in __init__
    (code, msg) = self.connect(host, port)
  File "/usr/lib/python3.8/smtplib.py", line 339, in connect
    self.sock = self._get_socket(host, port, self.timeout)
  File "/usr/lib/python3.8/smtplib.py", line 310, in _get_socket
    return socket.create_connection((host, port), timeout,
  File "/usr/lib/python3.8/socket.py", line 808, in create_connection
    raise err
  File "/usr/lib/python3.8/socket.py", line 796, in create_connection
    sock.connect(sa)
ConnectionRefusedError: [Errno 111] Connection refused

During handling of the above exception, another exception occurred:

Traceback (most recent call last):
  File "/home/lcscarv/projetos/indicium/desafio_5/.venv/lib/python3.8/site-packages/airflow/models/taskinstance.py", line 1837, in handle_failure
    self.email_alert(error, task)
  File "/home/lcscarv/projetos/indicium/desafio_5/.venv/lib/python3.8/site-packages/airflow/models/taskinstance.py", line 2241, in email_alert
    send_email(task.email, subject, html_content_err)
  File "/home/lcscarv/projetos/indicium/desafio_5/.venv/lib/python3.8/site-packages/airflow/utils/email.py", line 78, in send_email
    return backend(
  File "/home/lcscarv/projetos/indicium/desafio_5/.venv/lib/python3.8/site-packages/airflow/utils/email.py", line 152, in send_email_smtp
    send_mime_email(e_from=mail_from, e_to=recipients, mime_msg=msg, conn_id=conn_id, dryrun=dryrun)
  File "/home/lcscarv/projetos/indicium/desafio_5/.venv/lib/python3.8/site-packages/airflow/utils/email.py", line 270, in send_mime_email
    smtp_conn = _get_smtp_connection(smtp_host, smtp_port, smtp_timeout, smtp_ssl)
  File "/home/lcscarv/projetos/indicium/desafio_5/.venv/lib/python3.8/site-packages/airflow/utils/email.py", line 317, in _get_smtp_connection
    else smtplib.SMTP(host=host, port=port, timeout=timeout)
  File "/usr/lib/python3.8/smtplib.py", line 255, in __init__
    (code, msg) = self.connect(host, port)
  File "/usr/lib/python3.8/smtplib.py", line 339, in connect
    self.sock = self._get_socket(host, port, self.timeout)
  File "/usr/lib/python3.8/smtplib.py", line 310, in _get_socket
    return socket.create_connection((host, port), timeout,
  File "/usr/lib/python3.8/socket.py", line 808, in create_connection
    raise err
  File "/usr/lib/python3.8/socket.py", line 796, in create_connection
    sock.connect(sa)
ConnectionRefusedError: [Errno 111] Connection refused
[2023-05-03T14:02:02.685-0300] {standard_task_runner.py:100} ERROR - Failed to execute job 20 for task northwind_extract_ord_det (You are trying to merge on object and int64 columns. If you wish to proceed you should use pd.concat; 30241)
[2023-05-03T14:02:02.724-0300] {local_task_job.py:212} INFO - Task exited with return code 1
[2023-05-03T14:02:02.781-0300] {taskinstance.py:2596} INFO - 0 downstream tasks scheduled from follow-on schedule check
